Workbook

Sheet Screens_Asher
A1: Feature Rank | B1: Feature Title | C1: Feature ID | D1: Short Name | E1: Long Name | F1: Priority | G1: Design Notes | H1: Priority Notes | I1: Menu Folder | J1: Menu Abbreviation for URL | K1: Source (Web vs Classic) | L1: Source Form | M1: Query | N1: Input | O1: Process | P1: Query Detail Pair | Q1: Batch on Screen? | R1: Complex Batch? | S1: Prexisting screen? | T1: Commentary/Notes
A2: 1 | B2: =VLOOKUP(C2,Lookups!$G$2:$H$38,2,FALSE) -> 03 EAM - Screens - Direct Revenue Input | C2: 1786972 | D2: VL031 | E2: VL Direct Revenue Input | F2: 1 - Priority 1 | G2: Redesign to incorporate VL032 | I2: Revenue Distribution | J2: RD | K2: Classic Gui | L2: QFRMVLMANUALINPUTHTD | M2: Y | N2: Y | Q2: N | R2: N | S2: Y
A3: 1 | B3: =VLOOKUP(C3,Lookups!$G$2:$H$38,2,FALSE) -> 03 EAM - Screens - Direct Revenue Input | C3: 1786972 | D3: ML006 | E3: SOD DRI Links | F3: 1 - Priority 1 | G3: Lift and Shift with Minor redesign | I3: Revenue Distribution | J3: RD | K3: Classic Gui | L3: QFRMSODDRILINKS | M3: Y | N3: Y | Q3: N | R3: N
A4: 1 | B4: =VLOOKUP(C4,Lookups!$G$2:$H$38,2,FALSE) -> 03 EAM - Screens - Direct Revenue Input | C4: 1786972 | D4: VL025 | E4: DRI Link Maintenance | F4: 1 - Priority 1 | G4: Lift and Shift | I4: Revenue Distribution | J4: RD | K4: Classic Gui | L4: QFRMMILINKMAINTENANCE | M4: Y | N4: Y | Q4: N | R4: N
A5: 2 | B5: =VLOOKUP(C5,Lookups!$G$2:$H$38,2,FALSE) -> 05 EAM - Screens- Journal Entry - Setup Screens | C5: 1786978 | D5: JE005 | E5: JE Group Type Maintenance | F5: 1 - Priority 1 | G5: Lift and Shift | I5: Journal Entries | J5: JE | K5: Classic Gui | L5: QFRMGROUPTYPEMAINTENANCE | M5: Y | N5: Y | Q5: N | R5: N
A6: 2 | B6: =VLOOKUP(C6,Lookups!$G$2:$H$38,2,FALSE) -> 05 EAM - Screens- Journal Entry - Setup Screens | C6: 1786978 | D6: JE010 | E6: Account Setup Maintenance | F6: 1 - Priority 1 | G6: Lift and Shift | I6: Journal Entries | J6: JE | K6: Classic Gui | L6: QFRMACCTSETUPMAINTENANCE | M6: Y | N6: Y | Q6: N | R6: N
A7: 2 | B7: =VLOOKUP(C7,Lookups!$G$2:$H$38,2,FALSE) -> 05 EAM - Screens- Journal Entry - Setup Screens | C7: 1786978 | D7: JE011 | E7: Account/Subledger Xref | F7: 1 - Priority 1 | G7: Lift and Shift | I7: Journal Entries | J7: JE | K7: Classic Gui | L7: QFRMACCTSUBLEDGERXREF | M7: Y | N7: Y | Q7: N | R7: N
A8: 2 | B8: =VLOOKUP(C8,Lookups!$G$2:$H$38,2,FALSE) -> 05 EAM - Screens- Journal Entry - Setup Screens | C8: 1786978 | D8: JE015 | E8: Account Group | F8: 1 - Priority 1 | G8: Lift and Shift | I8: Journal Entries | J8: JE | K8: Classic Gui | L8: QFRMACCTGROUPMAINTENANCE | M8: Y | N8: Y | Q8: N | R8: N
A9: 2 | B9: =VLOOKUP(C9,Lookups!$G$2:$H$38,2,FALSE) -> 05 EAM - Screens- Journal Entry - Setup Screens | C9: 1786978 | D9: JE020 | E9: Account/Account Group Xref | F9: 1 - Priority 1 | G9: Lift and Shift | I9: Journal Entries | J9: JE | K9: Classic Gui | L9: QFRMACCTACCTGROUPXREF | M9: Y | N9: Y | Q9: N | R9: N
A10: 2 | B10: =VLOOKUP(C10,Lookups!$G$2:$H$38,2,FALSE) -> 05 EAM - Screens- Journal Entry - Setup Screens | C10: 1786978 | D10: JE025 | E10: Account Group Template | F10: 1 - Priority 1 | G10: Lift and Shift | I10: Journal Entries | J10: JE | K10: Classic Gui | L10: QFRMACCTGROUPTEMPLATE | M10: Y | N10: Y | Q10: N | R10: N
A11: 2 | B11: =VLOOKUP(C11,Lookups!$G$2:$H$38,2,FALSE) -> 05 EAM - Screens- Journal Entry - Setup Screens | C11: 1786978 | D11: JE030 | E11: Subledger Maintenance | F11: 1 - Priority 1 | G11: Lift and Shift | I11: Journal Entries | J11: JE | K11: Classic Gui | L11: QFRMSUBLEDGERMAINTENANCEDETAIL | M11: Y | N11: Y | Q11: N | R11: N
A12: 3 | B12: =VLOOKUP(C12,Lookups!$G$2:$H$38,2,FALSE) -> 06 EAM - Screens - Revenue Distribution - Processing | C12: 1786980 | D12: VL100 | E12: Revenue Selection/Submittal | F12: 1 - Priority 1 | G12: Redesign? | I12: Revenue Distribution | J12: RD | K12: Classic Gui | L12: QFRMREVENUESUBMISSION | M12: Y | O12: Y | Q12: Y | R12: Y
A13: 4 | B13: =VLOOKUP(C13,Lookups!$G$2:$H$38,2,FALSE) -> 07 EAM - Screens - Revenue Distribution - Setup | C13: 1792384 | D13: VL005 | E13: DOI Accounting Data Query | F13: 3 - Priority 3 | G13: Combine with VL006 | H13: Combine with data input | I13: Revenue Distribution | J13: RD | K13: Classic Gui | L13: QFRMDOIACCOUNTINGDATA | M13: Y | P13: Y | Q13: N | R13: N
A14: 4 | B14: =VLOOKUP(C14,Lookups!$G$2:$H$38,2,FALSE) -> 07 EAM - Screens - Revenue Distribution - Setup | C14: 1792384 | D14: VL006 | E14: DOI Accounting Rules | F14: 1 - Priority 1 | G14: Combine with VL005 | H14: Must have data input screen | I14: Revenue Distribution | J14: RD | K14: Classic Gui | L14: QFRMDOIACCOUNTINGDATAHEADERDETAIL | M14: Y | N14: Y | P14: Y | Q14: N | R14: N
A15: 4 | B15: =VLOOKUP(C15,Lookups!$G$2:$H$38,2,FALSE) -> 07 EAM - Screens - Revenue Distribution - Setup | C15: 1792384 | D15: TX020 | E15: State Tax Rate Query | F15: 1 - Priority 1 | G15: Lift and Shift | I15: Revenue Distribution | J15: RD | K15: Classic Gui | L15: QFRMSTATETAXRATEQUERY | M15: Y | P15: Y | Q15: N | R15: N
A16: 4 | B16: =VLOOKUP(C16,Lookups!$G$2:$H$38,2,FALSE) -> 07 EAM - Screens - Revenue Distribution - Setup | C16: 1792384 | D16: TX021 | E16: State Tax Rate Maintenance | F16: 1 - Priority 1 | G16: Lift and Shift | I16: Revenue Distribution | J16: RD | K16: Classic Gui | L16: QFRMSTATETAXRATE | N16: Y | Q16: N | R16: N
A17: 5 | B17: =VLOOKUP(C17,Lookups!$G$2:$H$38,2,FALSE) -> 04 EAM - Screens - Journal Entry - JE Processing Screens | C17: 1792329 | D17: JE100 | E17: JE Post Selection/Submittal | F17: 1 - Priority 1 | G17: Lift and Shift | I17: Journal Entries | J17: JE | K17: Classic Gui | L17: QFRMJEPOSTINGCONTROL | M17: Y | O17: Y | Q17: Y | R17: Y | S17: Y
A18: 5 | B18: =VLOOKUP(C18,Lookups!$G$2:$H$38,2,FALSE) -> 04 EAM - Screens - Journal Entry - JE Processing Screens | C18: 1792329 | D18: JE102 | E18: Accounting Month Roll Date | F18: 2 - Priority 2 | G18: Lift and Shift | H18: Batch Process Launcher | I18: Journal Entries | J18: JE | K18: Classic Gui | L18: QFRMACCTMNTHROLLDATE | M18: Y | O18: Y | Q18: Y | R18: Y | S18: Y
A19: 6 | B19: =VLOOKUP(C19,Lookups!$G$2:$H$38,2,FALSE) -> 09 EAM - Screens - Direct Revenue Input - Upload | C19: 1792365 | D19: VL032 | E19: VL Direct Revenue Input Upload | F19: 3 - Priority 3 | G19: Combine with VL031 | H19: Combine with other screen for single unified workflow | I19: Revenue Distribution | J19: RD | K19: Classic Gui | L19: QFRMVLMANUALINPUTUPLOAD | M19: Y | N19: Y | O19: Y | Q19: Y | R19: Y | S19: Y
A20: 7 | B20: =VLOOKUP(C20,Lookups!$G$2:$H$38,2,FALSE) -> 10 EAM - Screens - Revenue Distribution - Query Screens | C20: 1792382 | D20: RD031 | E20: RD Post Tracking Results | F20: 3 - Priority 3 | G20: Lift and Shift | H20: Query Screen Data Strategy? | I20: Revenue Distribution | J20: RD | K20: Classic Gui | L20: QFRMRDOWNERLEVELPOSTHISTORYQUERY | M20: Y | Q20: N | R20: N | S20: Y
A21: 7 | B21: =VLOOKUP(C21,Lookups!$G$2:$H$38,2,FALSE) -> 10 EAM - Screens - Revenue Distribution - Query Screens | C21: 1792382 | D21: RD030 | E21: RD Pre Tracking Results | F21: 3 - Priority 3 | G21: Lift and Shift | H21: Query Screen Data Strategy? | I21: Revenue Distribution | J21: RD | K21: Classic Gui | L21: QFRMRDOWNERLEVELHISTORYQUERY | M21: Y | Q21: N | R21: N
A22: 7 | B22: =VLOOKUP(C22,Lookups!$G$2:$H$38,2,FALSE) -> 10 EAM - Screens - Revenue Distribution - Query Screens | C22: 1792382 | D22: VL050 | E22: VL Full Revenue Results | F22: 3 - Priority 3 | G22: Lift and Shift | H22: Query Screen Data Strategy? | I22: Revenue Distribution | J22: RD | K22: Classic Gui | L22: QFRMVALTRANSQUERY | M22: Y | Q22: N | R22: N
A23: 7 | B23: =VLOOKUP(C23,Lookups!$G$2:$H$38,2,FALSE) -> 10 EAM - Screens - Revenue Distribution - Query Screens | C23: 1792382 | D23: RD010 | E23: Reversal DOI Deletion | F23: 3 - Priority 3 | G23: Lift and Shift | I23: Revenue Distribution | J23: RD | K23: Classic Gui | L23: QFRMREVERSALDODELETION | M23: Y | O23: Y | Q23: Y | R23: N
A24: 8 | B24: =VLOOKUP(C24,Lookups!$G$2:$H$38,2,FALSE) -> 11 EAM - Screens - Revenue Distribution - PPN | C24: 1792387 | D24: PN020 | E24: PPN Creation | F24: 1 - Priority 1 | G24: Mostly Lift and Shift Combine with PN025 | I24: Revenue Distribution | J24: RD | K24: Classic Gui | L24: QFrmPPNCreation | M24: Y | N24: Y | Q24: N | R24: N
A25: 8 | B25: =VLOOKUP(C25,Lookups!$G$2:$H$38,2,FALSE) -> 11 EAM - Screens - Revenue Distribution - PPN | C25: 1792387 | D25: PN025 | E25: PPN Query | F25: 3 - Priority 3 | G25: Combine with PN020 | H25: Combine with other screen | I25: Revenue Distribution | J25: RD | K25: Classic Gui | L25: QFrmPPNQuery | M25: Y | N25: Y | Q25: N | R25: N
A26: 9 | B26: =VLOOKUP(C26,Lookups!$G$2:$H$38,2,FALSE) -> 12 EAM - Screens - Journal Entry - Query Screens | C26: 1792326 | D26: JE101 | E26: Subledger Detail Query | F26: 3 - Priority 3 | G26: Lift and Shift | H26: Query Screen Data Strategy? | I26: Journal Entries | J26: JE | M26: Y | Q26: N | R26: N | S26: Y
A27: 9 | B27: =VLOOKUP(C27,Lookups!$G$2:$H$38,2,FALSE) -> 12 EAM - Screens - Journal Entry - Query Screens | C27: 1792326 | D27: JE110 | E27: GL MTD Detail Query | F27: 3 - Priority 3 | G27: Lift and Shift | H27: Exists in My Q Web; Query Screen Data Strategy? | I27: Journal Entries | J27: JE | K27: Classic Gui | L27: QFRMGENERALLEDGERDETAILQUERY | M27: Y | Q27: N | R27: N | S27: Y
A28: 9 | B28: =VLOOKUP(C28,Lookups!$G$2:$H$38,2,FALSE) -> 12 EAM - Screens - Journal Entry - Query Screens | C28: 1792326 | D28: JE111 | E28: GL History Detail Query | F28: 3 - Priority 3 | G28: Lift and Shift | H28: Exists in My Q Web; Query Screen Data Strategy? | I28: Journal Entries | J28: JE | K28: Classic Gui | L28: QFRMGENERALLEDGERDETAILHISTQUERY | M28: Y | Q28: N | R28: N | S28: Y
A29: 10 | B29: =VLOOKUP(C29,Lookups!$G$2:$H$38,2,FALSE) -> 13 EAM - Screens - Journal Entry - Manual Journal Entry Screens | C29: 1792325 | D29: JE205 | E29: Manual JE Batch Maintenance | F29: 1 - Priority 1 | G29: Redesign - Combine all MJE screens | H29: Must have MJE but should combine to single workflow | I29: Journal Entries | J29: JE | K29: Classic Gui | L29: QFRMMANUALJEBATCHMAINTENANCE | M29: Y | N29: Y | Q29: Y | R29: N | S29: Y
A30: 10 | B30: =VLOOKUP(C30,Lookups!$G$2:$H$38,2,FALSE) -> 13 EAM - Screens - Journal Entry - Manual Journal Entry Screens | C30: 1792325 | D30: JE210 | E30: Manual JE Batch Approval | F30: 2 - Priority 2 | G30: Redesign - Combine all MJE screens | H30: Must have MJE but should combine to single workflow | I30: Journal Entries | J30: JE | K30: Classic Gui | L30: QFRMMANUALJEBATCHAPPROVAL | M30: Y | O30: Y | Q30: Y | R30: Y | S30: Y
A31: 10 | B31: =VLOOKUP(C31,Lookups!$G$2:$H$38,2,FALSE) -> 13 EAM - Screens - Journal Entry - Manual Journal Entry Screens | C31: 1792325 | D31: JE206 | E31: Manual JE Detail | F31: 2 - Priority 2 | G31: Redesign - Combine all MJE screens | H31: Must have MJE but should combine to single workflow | I31: Journal Entries | J31: JE | K31: Classic Gui | L31: QFRMMANUALJEDETAIL | M31: Y | N31: Y | O31: Y | Q31: N | R31: N
A32: 10 | B32: =VLOOKUP(C32,Lookups!$G$2:$H$38,2,FALSE) -> 13 EAM - Screens - Journal Entry - Manual Journal Entry Screens | C32: 1792325 | D32: JE207 | E32: Manual JE Tax and Adj | F32: 2 - Priority 2 | G32: Redesign - Combine all MJE screens | H32: Must have MJE but should combine to single workflow | I32: Journal Entries | J32: JE | K32: Classic Gui | Q32: N | R32: N
A33: 11 | B33: =VLOOKUP(C33,Lookups!$G$2:$H$38,2,FALSE) -> 14 EAM - Screens - Journal Entry - Reversal Screens | C33: 1792327 | D33: JE305 | E33: HIST Reversal Batch Selection | F33: 2 - Priority 2 | G33: Redesign? | H33: EQT and BP only frequent users | I33: Journal Entries | J33: JE | K33: Classic Gui | L33: QFRMHISTORYREVERSALBATCHSELECTION | M33: Y | N33: Y | O33: Y | Q33: Y | R33: Y
A34: 11 | B34: =VLOOKUP(C34,Lookups!$G$2:$H$38,2,FALSE) -> 14 EAM - Screens - Journal Entry - Reversal Screens | C34: 1792327 | D34: JE310 | E34: HIST Reversal Batch Execution | F34: 2 - Priority 2 | G34: Redesign? | H34: EQT and BP only frequent users | I34: Journal Entries | J34: JE | K34: Classic Gui | L34: QFRMHISTORYREVERSALBATCHEXECUTION | M34: ? | Q34: Y | R34: Y
A35: 11 | B35: =VLOOKUP(C35,Lookups!$G$2:$H$38,2,FALSE) -> 14 EAM - Screens - Journal Entry - Reversal Screens | C35: 1792327 | D35: JE315 | E35: MTD Reversal Batch Selection | F35: 2 - Priority 2 | G35: Redesign? | H35: EQT and BP only frequent users | I35: Journal Entries | J35: JE | K35: Classic Gui | L35: QFRMMTDREVERSALBATCHSELECTION | M35: Y | N35: Y | O35: Y | Q35: Y | R35: Y
A36: 11 | B36: =VLOOKUP(C36,Lookups!$G$2:$H$38,2,FALSE) -> 14 EAM - Screens - Journal Entry - Reversal Screens | C36: 1792327 | D36: JE320 | E36: MTD Reversal Batch Execution | F36: 2 - Priority 2 | G36: Redesign? | H36: EQT and BP only frequent users | I36: Journal Entries | J36: JE | K36: Classic Gui | L36: QFRMMTDREVERSALBATCHEXECUTION | M36: ? | Q36: Y | R36: Y
A37: 12 | B37: =VLOOKUP(C37,Lookups!$G$2:$H$38,2,FALSE) -> 15 EAM - Screen - Check Write | C37: 1786986 | D37: CW005 | E37: Check Register Query/View | F37: 1 - Priority 1 | G37: Lift and Shift | I37: Check Write | J37: CW | K37: Web (or use Classic?) | Q37: Y | R37: Y | S37: Y
A38: 12 | B38: =VLOOKUP(C38,Lookups!$G$2:$H$38,2,FALSE) -> 15 EAM - Screen - Check Write | C38: 1786986 | D38: CW020 | E38: Void Check Maintenance | F38: 1 - Priority 1 | G38: Lift and Shift with Performance Improvements | I38: Check Write | J38: CW | K38: Classic Gui | Q38: Y | R38: Y | S38: Y
A39: 12 | B39: =VLOOKUP(C39,Lookups!$G$2:$H$38,2,FALSE) -> 15 EAM - Screen - Check Write | C39: 1786986 | D39: CW010 | E39: State Withholding Tax Maintenance | F39: 1 - Priority 1 | G39: Lift and Shift | I39: Check Write | J39: CW | K39: Classic Gui | L39: QFRMSTATEWITHHOLDINGTAX | M39: Y | N39: Y | Q39: N | R39: N
A40: 12 | B40: =VLOOKUP(C40,Lookups!$G$2:$H$38,2,FALSE) -> 15 EAM - Screen - Check Write | C40: 1786986 | D40: CW011 | E40: State Backup Withholding Tax Maintenance | F40: 1 - Priority 1 | G40: Lift and Shift | I40: Check Write | J40: CW | K40: Classic Gui | L40: QFRMSTATEBACKUPWITHHOLDINGTAXMAINT | M40: Y | N40: Y | Q40: N | R40: N
...

Sheet Screens_Old2
A1: Short Name | B1: Long Name | C1: Priority | D1: Design Notes | E1: Priority Notes | F1: Feature | G1: Menu Folder | H1: Menu Abbreviation for URL | I1: Source (Web vs Classic) | J1: Source Form | K1: Query | L1: Input | M1: Process | N1: Query Detail Pair
A2: CW010 | B2: State Withholding Tax Maintenance | C2: 1 - Priority 1 | D2: Lift and Shift | F2: 1786986 | G2: Check Write | H2: CW | I2: Classic Gui | J2: QFRMSTATEWITHHOLDINGTAX | K2: Y | L2: Y
A3: CW011 | B3: State Backup Withholding Tax Maintenance | C3: 1 - Priority 1 | D3: Lift and Shift | F3: 1786986 | G3: Check Write | H3: CW | I3: Classic Gui | J3: QFRMSTATEBACKUPWITHHOLDINGTAXMAINT | K3: Y | L3: Y
A4: CW015 | B4: Non-Resident Alien Withholding Tax Maintenance | C4: 1 - Priority 1 | D4: Lift and Shift | F4: 1786986 | G4: Check Write | H4: CW | I4: Classic Gui | J4: QFRMFOREIGNWITHHOLDINGTAX | K4: Y | L4: Y
A5: CW020 | B5: Void Check Maintenance | C5: 1 - Priority 1 | D5: Lift and Shift with Performance Improvements | F5: 1786986 | G5: Check Write | H5: CW | I5: Classic Gui
A6: CW005 | B6: Check Register Query/View | C6: 1 - Priority 1 | D6: Lift and Shift | F6: 1786986 | G6: Check Write | H6: CW | I6: Web (or use Classic?)
A7: EC005 | B7: Escheat Maintenance/History | C7: 2 - Priority 2 | D7: Lift and Shift | F7: 1786986 | G7: Check Write | H7: CW | I7: Classic Gui | J7: QFRMESCHEATMAINTENANCEHISTORY | K7: Y | L7: Y
A8: EC010 | B8: Escheat Processing Rules | C8: 2 - Priority 2 | D8: Lift and Shift | F8: 1786986 | G8: Check Write | H8: CW | I8: Classic Gui | J8: QFRMESCHEATPROCESSINGRULES | K8: Y | L8: Y
A9: RC005 | B9: Contract Maintenance | C9: 1 - Priority 1 | D9: Lift and Shift | F9: 1786987 | G9: Contracts | H9: CTR | I9: Classic Gui | J9: QFRMCTRMAINT | K9: Y | L9: Y
A10: RC036 | B10: Price Terms Maintenance | C10: 1 - Priority 1 | D10: Lift and Shift | F10: 1786987 | G10: Contracts | H10: CTR | I10: Classic Gui | J10: QFRMPRICETERMSMAINT | K10: Y | L10: Y
A11: DO004 | B11: DOI Header Query | C11: 3 - Priority 3 | D11: Lift and Shift | E11: Can resort to QDO Web | F11: 1786975 | G11: Division of Interest | H11: DOI | I11: Classic Gui | K11: Y | N11: Y
A12: DO005 | B12: DOI Query | C12: 3 - Priority 3 | D12: Lift and Shift | E12: Can resort to QDO Web | F12: 1786975 | G12: Division of Interest | H12: DOI | I12: Classic Gui | K12: Y | N12: Y
A13: DO006 | B13: DOI Setup | C13: 3 - Priority 3 | D13: Lift and Shift | E13: Can resort to QDO Web | F13: 1786975 | G13: Division of Interest | H13: DOI | I13: Web | J13: QDO.WEB.Views/DonlDoHDr | K13: Y | L13: Y
A14: DO016 | B14: MEG Setup | C14: 3 - Priority 3 | D14: Redesign? | E14: Can resort to QDO Web | F14: 1786975 | G14: Division of Interest | H14: DOI | I14: Web | J14: Quorum.QDO.Web/Views/DonlMktExmpGrpHdr | K14: Y | L14: Y
A15: DO105 | B15: DOI History | C15: 3 - Priority 3 | D15: Lift and Shift | E15: Can resort to QDO Web | F15: 1786975 | G15: Division of Interest | H15: DOI | I15: Web | J15: Quorum.QDO.Web/Views/DOIHistory | K15: Y
A16: DO999 | B16: DOI Search | C16: 3 - Priority 3 | D16: Lift and Shift | E16: Can resort to QDO Web | F16: 1786975 | G16: Division of Interest | H16: DOI | I16: Web
A17: DO999 | B17: Owner Search | C17: 3 - Priority 3 | D17: Lift and Shift | E17: Can resort to QDO Web | F17: 1786975 | G17: Division of Interest | H17: DOI | I17: Web | N17: These are on the dashboard - need to test
A18: DO999 | B18: Pending DOIs | C18: 3 - Priority 3 | D18: Lift and Shift | E18: Can resort to QDO Web | F18: 1786975 | G18: Division of Interest | H18: DOI | I18: Web | N18: These are on the dashboard - need to test
A19: DO999 | B19: Pending Maintenance | C19: 3 - Priority 3 | D19: Lift and Shift | E19: Can resort to QDO Web | F19: 1786975 | G19: Division of Interest | H19: DOI | I19: Web
A20: DO999 | B20: Pending Market Groups | C20: 3 - Priority 3 | D20: Lift and Shift | E20: Can resort to QDO Web | F20: 1786975 | G20: Division of Interest | H20: DOI | I20: Web
A21: DO999 | B21: Maintenance Wizard (Maintenance Group Creation, Maintenance Group, Transaction wizard from Elixir) | C21: 3 - Priority 3 | D21: Redesign (some elements) | E21: Can resort to QDO Web | F21: 1786975 | G21: Division of Interest | H21: DOI
A22: MG004 | B22: Market Group Header Query | C22: 3 - Priority 3 | D22: Lift and Shift | F22: 1786975 | G22: Division of Interest | H22: DOI | I22: Classic Gui
A23: MG005 | B23: Market Group Query | C23: 3 - Priority 3 | D23: Lift and Shift | E23: Can resort to QDO Web | F23: 1786975 | G23: Division of Interest | H23: DOI | I23: Classic Gui | J23: QFRMMARKETGROUPQUERY | K23: Y | N23: Y
A24: MG006 | B24: Market Group | C24: 2 - Priority 2 | D24: Lift and Shift | E24: Can use existing web screen | F24: 1786975 | G24: Division of Interest | H24: DOI | I24: Web | K24: Y | L24: Y | N24: Y
A25: BA005 | B25: Business Assocate | C25: 3 - Priority 3 | D25: Lift and Shift - But strip Midstream Needs? | E25: Can Revert to Esuite Web | F25: 1786985 | G25: Esuite | H25: Esuite | I25: Web (or use Classic?)
A26: BA010 | B26: BA Mass Update | C26: 3 - Priority 3 | D26: Lift and Shift from Classic | E26: Can Revert to Esuite Web | F26: 1786985 | G26: Esuite | H26: Esuite | I26: Classic Gui
A27: BA015 | B27: BA Address Mass Update | C27: 3 - Priority 3 | D27: Lift and Shift from Classic | E27: Can Revert to Esuite Web | F27: 1786985 | G27: Esuite | H27: Esuite | I27: Classic Gui
A28: BA030 | B28: Contact Maintenance | C28: 3 - Priority 3 | D28: Lift and Shift from Classic | E28: Can Revert to Esuite Web | F28: 1786985 | G28: Esuite | H28: Esuite | I28: Web (or use Classic?)
A29: CC010 | B29: Cost Center Maintenance | C29: 3 - Priority 3 | D29: Lift and Shift | E29: Can Revert to Esuite Web | F29: 1786985 | G29: Esuite | H29: Esuite | I29: Web | K29: Y | L29: Y
A30: GB015 | B30: Gas Balancing Manual Input | C30: 2 - Priority 2 | D30: Lift and Shift | F30: 1786987 | G30: Gas Balancing | H30: GB | I30: Classic Gui | J30: QFRMGASBALMANUAL | K30: Y | L30: Y
A31: JE005 | B31: JE Group Type Maintenance | C31: 1 - Priority 1 | D31: Lift and Shift | F31: 1786978 | G31: Journal Entries | H31: JE | I31: Classic Gui | J31: QFRMGROUPTYPEMAINTENANCE | K31: Y | L31: Y
A32: JE010 | B32: Account Setup Maintenance | C32: 1 - Priority 1 | D32: Lift and Shift | F32: 1786978 | G32: Journal Entries | H32: JE | I32: Classic Gui | J32: QFRMACCTSETUPMAINTENANCE | K32: Y | L32: Y
A33: JE011 | B33: Account/Subledger Xref | C33: 1 - Priority 1 | D33: Lift and Shift | F33: 1786978 | G33: Journal Entries | H33: JE | I33: Classic Gui | J33: QFRMACCTSUBLEDGERXREF | K33: Y | L33: Y
A34: JE015 | B34: Account Group | C34: 1 - Priority 1 | D34: Lift and Shift | F34: 1786978 | G34: Journal Entries | H34: JE | I34: Classic Gui | J34: QFRMACCTGROUPMAINTENANCE | K34: Y | L34: Y
A35: JE020 | B35: Account/Account Group Xref | C35: 1 - Priority 1 | D35: Lift and Shift | F35: 1786978 | G35: Journal Entries | H35: JE | I35: Classic Gui | J35: QFRMACCTACCTGROUPXREF | K35: Y | L35: Y
A36: JE025 | B36: Account Group Template | C36: 1 - Priority 1 | D36: Lift and Shift | F36: 1786978 | G36: Journal Entries | H36: JE | I36: Classic Gui | J36: QFRMACCTGROUPTEMPLATE | K36: Y | L36: Y
A37: JE030 | B37: Subledger Maintenance | C37: 1 - Priority 1 | D37: Lift and Shift | F37: 1786978 | G37: Journal Entries | H37: JE | I37: Classic Gui | J37: QFRMSUBLEDGERMAINTENANCEDETAIL | K37: Y | L37: Y
A38: JE100 | B38: JE Post Selection/Submittal | C38: 1 - Priority 1 | D38: Lift and Shift | F38: 1786978 | G38: Journal Entries | H38: JE | I38: Classic Gui | J38: QFRMJEPOSTINGCONTROL | K38: Y | M38: Y
A39: JE102 | B39: Accounting Month Roll Date | C39: 2 - Priority 2 | D39: Lift and Shift | E39: Batch Process Launcher | F39: 1786978 | G39: Journal Entries | H39: JE | I39: Classic Gui | J39: QFRMACCTMNTHROLLDATE | K39: Y | M39: Y
A40: JE110 | B40: GL MTD Detail Query | C40: 3 - Priority 3 | D40: Lift and Shift | E40: Exists in My Q Web; Query Screen Data Strategy? | F40: 1786978 | G40: Journal Entries | H40: JE | I40: Classic Gui | J40: QFRMGENERALLEDGERDETAILQUERY | K40: Y
...

Sheet Screens_Old1
A1: Short Name | B1: Long Name | C1: Menu Folder | D1: Menu Abbreviation for URL | E1: Source (Web vs Classic) | F1: Source Form | G1: Query | H1: Input | I1: Process | J1: Query Detail Pair | K1: POC Status | M1: My Q Web Status
A2: CW010 | B2: State Withholding Tax Maintenance | C2: Check Write | D2: CW | E2: Classic Gui | F2: QFRMSTATEWITHHOLDINGTAX | G2: Y | H2: Y | K2: =VLOOKUP(A2,Sheet1!A:G, 4, FALSE) -> ~75% feature parity achieved
A3: CW011 | B3: State Backup Withholding Tax Maintenance | C3: Check Write | D3: CW | E3: Classic Gui | F3: QFRMSTATEBACKUPWITHHOLDINGTAXMAINT | G3: Y | H3: Y | K3: =VLOOKUP(A3,Sheet1!A:G, 4, FALSE) -> #N/A
A4: CW015 | B4: Non-Resident Alien Withholding Tax Maintenance | C4: Check Write | D4: CW | E4: Classic Gui | F4: QFRMFOREIGNWITHHOLDINGTAX | G4: Y | H4: Y | K4: =VLOOKUP(A4,Sheet1!A:G, 4, FALSE) -> ~85% feature parity achieved (updated 2026-01-14)
A5: CW020 | B5: Void Check Maintenance | C5: Check Write | D5: CW | E5: Classic Gui
A6: EC005 | B6: Escheat Maintenance/History | C6: Check Write | D6: CW | E6: Classic Gui | F6: QFRMESCHEATMAINTENANCEHISTORY | G6: Y | H6: Y | K6: =VLOOKUP(A6,Sheet1!A:G, 4, FALSE) -> ~75% feature parity achieved
A7: EC010 | B7: Escheat Processing Rules | C7: Check Write | D7: CW | E7: Classic Gui | F7: QFRMESCHEATPROCESSINGRULES | G7: Y | H7: Y | K7: =VLOOKUP(A7,Sheet1!A:G, 4, FALSE) -> #N/A
A8: RC005 | B8: Contract Maintenance | C8: Contracts | D8: CTR | E8: Classic Gui | F8: QFRMCTRMAINT | G8: Y | H8: Y | K8: =VLOOKUP(A8,Sheet1!A:G, 4, FALSE) -> #N/A
A9: RC036 | B9: Price Terms Maintenance | C9: Contracts | D9: CTR | E9: Classic Gui | F9: QFRMPRICETERMSMAINT | G9: Y | H9: Y | K9: =VLOOKUP(A9,Sheet1!A:G, 4, FALSE) -> #N/A
B10: DOI Search | C10: Division of Interest | D10: DOI | E10: Web
B11: Owner Search | C11: Division of Interest | D11: DOI | E11: Web | J11: These are on the dashboard - need to test | K11: =VLOOKUP(B11,Sheet1!A:G, 4, FALSE) -> #N/A
B12: Pending DOIs | C12: Division of Interest | D12: DOI | E12: Web | J12: These are on the dashboard - need to test | K12: =VLOOKUP(B12,Sheet1!A:G, 4, FALSE) -> #N/A
B13: Pending Maintenance | C13: Division of Interest | D13: DOI | E13: Web
B14: Pending Market Groups | C14: Division of Interest | D14: DOI | E14: Web
A15: DO004 | B15: DOI Header Query | C15: Division of Interest | D15: DOI | E15: Classic Gui | G15: Y | J15: Y | K15: =VLOOKUP(A15,Sheet1!A:G, 4, FALSE) -> ~55% feature parity achieved (basic query functionality complete)
A16: DO005 | B16: DOI Query | C16: Division of Interest | D16: DOI | E16: Classic Gui | G16: Y | J16: Y | K16: =VLOOKUP(A16,Sheet1!A:G, 4, FALSE) -> ~75% feature parity achieved
A17: DO006 | B17: DOI Setup | C17: Division of Interest | D17: DOI | E17: Web | F17: QDO.WEB.Views/DonlDoHDr | G17: Y | H17: Y | K17: =VLOOKUP(A17,Sheet1!A:G, 4, FALSE) -> ~65% feature parity achieved
A18: DO016 | B18: MEG Setup | C18: Division of Interest | D18: DOI | E18: Web | F18: Quorum.QDO.Web/Views/DonlMktExmpGrpHdr | G18: Y | H18: Y | K18: =VLOOKUP(A18,Sheet1!A:G, 4, FALSE) -> ~90% feature parity achieved
A19: DO105 | B19: DOI History | C19: Division of Interest | D19: DOI | E19: Web | F19: Quorum.QDO.Web/Views/DOIHistory | G19: Y | K19: =VLOOKUP(A19,Sheet1!A:G, 4, FALSE) -> #N/A
A20: Maintenance Group Creation, Maintenance Group, Transaction wizard from Elixir | C20: Division of Interest | D20: DOI | J20: Sarah Will Do | K20: =VLOOKUP(A20,Sheet1!A:G, 4, FALSE) -> #N/A
A21: MG004 | B21: Market Group Header Query | C21: Division of Interest | D21: DOI | E21: Classic Gui | K21: =VLOOKUP(A21,Sheet1!A:G, 4, FALSE) -> #N/A
A22: MG005 | B22: Market Group Query | C22: Division of Interest | D22: DOI | E22: Classic Gui | F22: QFRMMARKETGROUPQUERY | G22: Y | J22: Y | K22: =VLOOKUP(A22,Sheet1!A:G, 4, FALSE) -> ~60% feature parity achieved (Query only)
A23: MG005 | B23: Market Group Detail Query | C23: Division of Interest | D23: DOI | E23: Classic Gui | K23: =VLOOKUP(A23,Sheet1!A:G, 4, FALSE) -> ~60% feature parity achieved (Query only)
A24: MG006 | B24: Market Group | C24: Division of Interest | D24: DOI | E24: Web | G24: Y | H24: Y | J24: Y | K24: =VLOOKUP(A24,Sheet1!A:G, 4, FALSE) -> ~75% feature parity achieved
A25: GB015 | B25: Gas Balancing Manual Input | C25: Gas Balancing | D25: GB | E25: Classic Gui | F25: QFRMGASBALMANUAL | G25: Y | H25: Y | K25: =VLOOKUP(A25,Sheet1!A:G, 4, FALSE) -> ~75% feature parity achieved
A26: JE005 | B26: JE Group Type Maintenance | C26: Journal Entries | D26: JE | E26: Classic Gui | F26: QFRMGROUPTYPEMAINTENANCE | G26: Y | H26: Y | K26: =VLOOKUP(A26,Sheet1!A:G, 4, FALSE) -> ~85% feature parity achieved
A27: JE010 | B27: Account Setup Maintenance | C27: Journal Entries | D27: JE | E27: Classic Gui | F27: QFRMACCTSETUPMAINTENANCE | G27: Y | H27: Y | K27: =VLOOKUP(A27,Sheet1!A:G, 4, FALSE) -> ~85% feature parity achieved
A28: JE011 | B28: Account/Subledger Xref | C28: Journal Entries | D28: JE | E28: Classic Gui | F28: QFRMACCTSUBLEDGERXREF | G28: Y | H28: Y | K28: =VLOOKUP(A28,Sheet1!A:G, 4, FALSE) -> ~85% feature parity achieved
A29: JE015 | B29: Account Group | C29: Journal Entries | D29: JE | E29: Classic Gui | F29: QFRMACCTGROUPMAINTENANCE | G29: Y | H29: Y | K29: =VLOOKUP(A29,Sheet1!A:G, 4, FALSE) -> ~92% feature parity achieved
A30: JE020 | B30: Account/Account Group Xref | C30: Journal Entries | D30: JE | E30: Classic Gui | F30: QFRMACCTACCTGROUPXREF | G30: Y | H30: Y | K30: =VLOOKUP(A30,Sheet1!A:G, 4, FALSE) -> #N/A
A31: JE025 | B31: Account Group Template | C31: Journal Entries | D31: JE | E31: Classic Gui | F31: QFRMACCTGROUPTEMPLATE | G31: Y | H31: Y | K31: =VLOOKUP(A31,Sheet1!A:G, 4, FALSE) -> ~78% feature parity achieved
A32: JE030 | B32: Subledger Maintenance | C32: Journal Entries | D32: JE | E32: Classic Gui | F32: QFRMSUBLEDGERMAINTENANCEDETAIL | G32: Y | H32: Y | K32: =VLOOKUP(A32,Sheet1!A:G, 4, FALSE) -> #N/A
A33: JE100 | B33: JE Post Selection/Submittal | C33: Journal Entries | D33: JE | E33: Classic Gui | F33: QFRMJEPOSTINGCONTROL | G33: Y | I33: Y | K33: =VLOOKUP(A33,Sheet1!A:G, 4, FALSE) -> ~65% feature parity achieved
A34: JE102 | B34: Accounting Month Roll Date | C34: Journal Entries | D34: JE | E34: Classic Gui | F34: QFRMACCTMNTHROLLDATE | G34: Y | I34: Y | K34: =VLOOKUP(A34,Sheet1!A:G, 4, FALSE) -> #N/A
A35: JE110 | B35: GL MTD Detail Query | C35: Journal Entries | D35: JE | E35: Classic Gui | F35: QFRMGENERALLEDGERDETAILQUERY | G35: Y | K35: =VLOOKUP(A35,Sheet1!A:G, 4, FALSE) -> ~75% feature parity achieved
A36: JE111 | B36: GL History Detail Query | C36: Journal Entries | D36: JE | E36: Classic Gui | F36: QFRMGENERALLEDGERDETAILHISTQUERY | G36: Y | K36: =VLOOKUP(A36,Sheet1!A:G, 4, FALSE) -> ~75% feature parity achieved
A37: JE205 | B37: Manual JE Batch Maintenance | C37: Journal Entries | D37: JE | E37: Classic Gui | F37: QFRMMANUALJEBATCHMAINTENANCE | G37: Y | H37: Y | K37: =VLOOKUP(A37,Sheet1!A:G, 4, FALSE) -> ~55% feature parity achieved
A38: JE205 | B38: Manual JE Batch Maintenance | C38: Journal Entries | D38: JE | E38: Classic Gui | F38: QFRMMANUALJEBATCHMAINTENANCE | G38: Y | H38: Y | K38: =VLOOKUP(A38,Sheet1!A:G, 4, FALSE) -> ~55% feature parity achieved
A39: JE206 | B39: Manual JE Detail | C39: Journal Entries | D39: JE | E39: Classic Gui | F39: QFRMMANUALJEDETAIL | G39: Y | H39: Y | I39: Y | K39: =VLOOKUP(A39,Sheet1!A:G, 4, FALSE) -> ~65% feature parity achieved
A40: JE206 | B40: Manual JE Detail | C40: Journal Entries | D40: JE | E40: Classic Gui | F40: QFRMMANUALJEDETAIL | H40: Y | K40: =VLOOKUP(A40,Sheet1!A:G, 4, FALSE) -> ~65% feature parity achieved
...

Sheet Sheet1
A1: Screen Code | B1: Screen Name | C1: Screen Purpose | D1: Current Status | E1: Critical Gaps | F1: What's Working | G1: Critical Missing Features
A2: CC010 | B2: Cost Center Maintenance | C2: N/A | D2: ~40% feature parity achieved | E2: 35 identified (22 CRITICAL, 13 MODERATE) | F2: N/A
A3: CW005 | B3: Check Register Query/View | C3: N/A | D3: ~35% feature parity achieved | E3: 28 identified (16 CRITICAL, 12 MODERATE) | F3: N/A | G3: N/A
A4: CW010 | B4: State Withholding Tax Maintenance | C4: N/A | D4: ~75% feature parity achieved | E4: 12 identified (6 CRITICAL, 4 MODERATE, 2 LOW) | F4: N/A | G4: N/A
A5: CW015 | B5: Non-Resident Alien Withholding Tax Maintenance | C5: N/A | D5: ~85% feature parity achieved (updated 2026-01-14) | E5: 8 identified (3 CRITICAL, 3 MODERATE, 2 LOW) | F5: N/A | G5: N/A
A6: DO004 | B6: DOI Header Query | C6: N/A | D6: ~55% feature parity achieved (basic query functionality complete) | E6: 18 identified (12 CRITICAL, 6 MODERATE) | F6: N/A
A7: DO005 | B7: DOI Query | C7: N/A | D7: ~75% feature parity achieved | E7: 15 identified (8 CRITICAL, 7 MODERATE) | F7: N/A | G7: N/A
A8: DO006 | B8: DOI Setup | C8: N/A | D8: ~65% feature parity achieved | E8: 28 identified (15 CRITICAL, 13 MODERATE) | F8: N/A | G8: N/A
A9: DO016 | B9: Market Exemption Group | C9: N/A | D9: ~90% feature parity achieved | E9: 8 identified (3 CRITICAL, 5 MODERATE) | F9: N/A | G9: N/A
A10: EC005 | B10: Escheat Maintenance/History | C10: N/A | D10: ~75% feature parity achieved | E10: 15 identified (8 CRITICAL, 7 MODERATE) | F10: N/A | G10: N/A
A11: GB015 | B11: Gas Balancing Manual Input | C11: Manual entry and management of gas balance transactions with inline grid editing, change tracking, and volume calculations | D11: ~75% feature parity achieved | E11: 7 identified (3 CRITICAL, 4 MODERATE) | F11: Filter section with all search criteria, Results grid with inline editing, CRUD operations, Volume calculations, Balance checking, Lookups & dropdowns, Security checks | G11: GMI/GWI Integration, Comments/Notes, Grid column configuration from metadata, Advanced business rule validation
A12: JE005 | B12: JE Group Type Maintenance | C12: Master-detail maintenance screen for JE Group Type configurations | D12: ~85% feature parity achieved | E12: 9 identified (3 CRITICAL, 4 MODERATE, 2 LOW) | F12: Blazor component rendering, Basic CRUD operations, Master-detail grid with inline editing, Change tracking and row state management, Security checks, DTOs and service layer | G12: Business rule validation incomplete (6 validation rules not implemented), GL_MTD_SUM_FL handling unclear, Configuration metadata integration missing
A13: JE010 | B13: Account Setup Maintenance | C13: N/A | D13: ~85% feature parity achieved | E13: 8 identified (3 CRITICAL, 5 MODERATE) | F13: N/A | G13: N/A
A14: JE011 | B14: Account/Subledger Xref | C14: N/A | D14: ~85% feature parity achieved | E14: 8 identified (3 CRITICAL, 5 MODERATE) | F14: N/A | G14: N/A
A15: JE015 | B15: Account Group | C15: Inline grid maintenance for account group configurations with 17 editable columns | D15: ~92% feature parity achieved | E15: 4 identified (2 CRITICAL, 2 MODERATE) | F15: Core inline grid editing with 17 editable columns, Composite primary key management, Row state tracking (Added/Modified/Deleted), Bulk save with transaction support, Comprehensive validation (2 business rules), Affiliate flag conditional behavior, Security check and maintenance privilege | G15: Account Group Number field shows numeric incrementer (violates UI standards), JE020 cross-reference validation not fully integrated (missing visual indicator and navigation)
A16: JE025 | B16: Account Group Template | C16: Maintenance screen for account group template records with inline editing across events, keywords, and account groups | D16: ~78% feature parity achieved | E16: 18 identified (8 CRITICAL, 6 MODERATE, 4 LOW) | F16: Full CRUD operations, Inline grid editing with visual state indicators, Lookup data management (Events, Keywords, Clear Types, Account Groups), Bulk save with transaction processing, Row state tracking | G16: Complex business rules (VALIDATE_REVERSAL_SIGN_ON_DELETING_RECORD, REVERSE_SIGN_FLIPPED), History/audit functionality, Primary key change handling verification, QARCH_CNFG_CTRL configuration integration, Grid column configuration from metadata
A17: JE100 | B17: JE Post Selection/Submittal | C17: Query and execution screen for JE posting control with batch job submission for JEPOSTONLY, TAXJEPOST, and TAXCOMBO processes | D17: ~65% feature parity achieved | E17: 15 identified (8 CRITICAL, 5 MODERATE, 2 LOW) | F17: Master-detail grid layout, Filter panel with all search criteria, Parent grid (20+ columns) and child grid, Multi-select support, Basic query functionality, Prevent Posting flag updates, Security and permission checks | G17: Batch job integration (cannot actually post JE batches), Clean/Undo/Rerun functionality, Comment requirements for prevent posting, Advanced validation rules, Reports integration, Configuration features
A18: JE110 | B18: GL MTD Detail Query | C18: N/A | D18: ~75% feature parity achieved | E18: 14 identified (7 CRITICAL, 5 MODERATE, 2 LOW) | F18: N/A | G18: N/A
A19: JE111 | B19: GL History Detail Query | C19: Query screen for GL History detail records with tax and adjustment category child grids | D19: ~75% feature parity achieved | E19: 10 identified (4 CRITICAL, 4 MODERATE, 2 LOW) | F19: Three-panel layout (main grid + two child grids), Comprehensive filter panel with required filter validation, 30+ display columns with LEFT JOINs, Tax child grid and Adjustment child grid, Totals calculation, BOOK_REV_WELL_COMPL configuration | G19: Excel export, Bulk edit/copy feature, Grid aggregation in footer, Grid configuration from metadata, Negative value styling, Filter row in grid header
A20: JE205 | B20: Manual JE Batch Maintenance | C20: N/A | D20: ~55% feature parity achieved | E20: 28 identified (16 CRITICAL, 12 MODERATE) | F20: N/A
A21: JE206 | B21: Manual JE Detail | C21: N/A | D21: ~65% feature parity achieved | E21: 31 identified (18 CRITICAL, 13 MODERATE) | F21: N/A | G21: N/A
A22: JE310 | B22: HIST Reversal Batch Execution | C22: Query and execution screen for GL History reversal batches with flag toggle and batch processing | D22: ~92% feature parity achieved | E22: 8 identified (0 CRITICAL, 3 MODERATE, 5 LOW) | F22: Complete filter panel (11 filters), Multi-select grid with reversal flag toggle, Transaction total calculation, Bulk execution with validation, Control record creation, User-scoped staging queries, All 10 business rules implemented | G22: Batch process launch deferred (requires QP043), Progress dialog missing, Numeric fields use MudNumericField (minor UI issue)
A23: JE315 | B23: MTD Reversal Batch Selection | C23: N/A | D23: ~85% feature parity achieved | E23: 8 identified (4 CRITICAL, 3 MODERATE, 1 LOW) | F23: N/A | G23: N/A
A24: MF035 | B24: Code Table Value Editor | C24: N/A | D24: ~65% feature parity achieved | E24: 28 identified (15 CRITICAL, 8 MODERATE, 5 LOW) | F24: N/A | G24: N/A
A25: MG005 | B25: Market Group Query | C25: Query screen for market group records with inquiry date filtering; navigation to MG006 maintenance screen | D25: ~60% feature parity achieved (Query only) | E25: 28 identified (15 CRITICAL, 8 MODERATE, 5 LOW) | F25: Query functionality with comprehensive filters (Property, DO Type, Tier, Major Product, Market Group Type/Status, Owner/Market Rep, Inquiry Date), Results grid, Maintenance navigation, Inquiry date logic, Security checks | G25: MG006 Maintenance screen (full CRUD, validation, business rules), 25+ business rules, Batch integration (GMI calculation, reversal creation, DO market group creation), Market group type-based security, Detail grid editing
A26: MG006 | B26: Market Group | C26: N/A | D26: ~75% feature parity achieved | E26: 18 identified (11 CRITICAL, 7 MODERATE) | F26: N/A | G26: N/A
A27: ML006 | B27: SOD DRI Links | C27: ML006 (SOD DRI Links) manages the cross-reference between Master Input (MI/DRI - Direct Revenue Input) records and SOD (Sales Order Deck) contracts. This is a critical screen for revenue accounting that links remitter statements to sales contracts for revenue distribution calculations. | D27: ~65% feature parity achieved | E27: 18 identified (10 CRITICAL, 5 MODERATE, 3 LOW) | F27: Filter/query functionality with 9 filter criteria; Grid display with 18 columns from legacy GRID_ID 9105; Inline editing for SOD Contract No and SOD Group No; Row state tracking (Modified/Deleted visual indicators); Bulk save with validation (SAVE_ONLY_APPROVED_SOD_CONTRACTS, CHECK_FOR_SOD_CONTRACTS); Delete and undo delete actions; Basic security check (QFRMSODDRILINKS); Read-only Playwright E2E tests; Component tests (instantiation, routing, access control) | G27: Mass Insert functionality (bulk creation of SOD links); Effective date logic (end-dating creates new row); Effective date overlap validation (EFFECTIVE_DATE_RXRF_MI_SOD_OVERLAP_CHECK); Multiple contracts validation (VALIDATE_MULTIPLE_CONTRACTS); SOD contract/group autocomplete with search; RELAX_UPDATE_PERMISSIONS framework-level permission logic; Excel Import/Export functionality; Configuration-driven column visibility; PPN (Post Process Notification) record creation for downstream batch processing; VL finalization status check (read-only when finalized)
A28: PD035 | B28: Well Completion | C28: Complex multi-tab maintenance screen for well completion master data with 11 functional tabs including effective dates, operators, theo rules, and land/legal | D28: ~35% feature parity achieved | E28: 29+ identified (12+ CRITICAL in header, plus more in child tabs) | F28: Basic CRUD for main header, Well completion search/lookup, Primary key fields and location fields, GPS coordinates, Classification fields, Approval workflow, Code table lookups (Countries, States, etc.), Read-only child data tabs (Effective Dates, Operators, Theo Rules, Land/Legal) | G28: 7 of 11 child tabs (editable grids not implemented), Parent well completion picker, Associated cost center picker, Configuration-driven field visibility (BookRevWellLvl, WcHideProspect), 17 validation rules, Complex QPA integration, Field/Well/Completion validation
A29: PN010 | B29: PPN Comments Dialog | C29: N/A | D29: ~10% feature parity achieved | E29: 18 identified (12 CRITICAL, 6 MODERATE) | G29: N/A
A30: PR005 | B30: Property | C30: N/A | D30: ~70% feature parity achieved (updated 2026-01-14) | E30: 22 identified (16 CRITICAL, 6 MODERATE) - 6 items completed in recent work | F30: N/A
A31: QP010 | B31: Process Execution Monitor | C31: Real-time process execution monitoring with steps, parameters, children, messages, and locks display | D31: ~85% feature parity achieved | E31: 4 identified (2 CRITICAL, 2 MODERATE) | F31: Complete process header display with all key fields, 5 tabbed sections (Steps, Parameters, Children, Messages, Locks), Process cancellation functionality, Recursive child process loading, Navigation between related processes, Security access control | G31: Auto-refresh timer (configurable 30-600 seconds), Message type multi-select filtering, Process hierarchy visualization enhancements, "View More Messages" pagination
A32: QP043 | B32: Process Launcher - QRA | C32: Process launcher for QRA batch processes with parameter management, server/step selection, and scheduling | D32: ~45% feature parity achieved | E32: 18 identified (8 CRITICAL, 6 MODERATE, 4 LOW) | F32: Process type/selection dropdowns, Step selection (if allowed), Server/Server group selection, Debug mode checkbox, Quick schedule, Basic parameter input (text, number, date, boolean, code table), Process execution, Saved parameters (partial), Security checks | G32: Parameter validation framework, Advanced parameter types (multi-value, range, dependent, file picker), Favorites system, Recent processes, Linked reports, Business rules integration, Real-time execution feedback
A33: QP045 | B33: Process Execution Monitor Query | C33: Query screen for batch process queue with filtering by status, dates, user, and module context | D33: ~70% feature parity achieved | E33: 20 identified (7 CRITICAL, 8 MODERATE, 5 LOW) | F33: Process Queue ID/Process ID filters, Status/Status Category dropdowns, User ID filter, Max Rows selector, Queue Date From/To pickers, Master Process Queue ID filter, Results grid with 11+ columns, Navigation to QP010, Duration calculation, Security check | G33: Module code filtering, Grid configuration from metadata (33 columns in metadata), Filter persistence, Context menu actions, "More All" functionality, Column sorting/filtering configuration, Process cancellation UI
A34: QP085 | B34: Report Launcher - QRA | C34: Report launcher for QRA reports with output format selection (PDF, Excel, CSV, HTML) and parameter management | D34: ~65% feature parity achieved | E34: 18 identified (8 CRITICAL, 6 MODERATE, 4 LOW) | F34: Report type/selection dropdowns, Output format selection, Basic parameter grid rendering, Saved parameter sets (local/global), Schedule for later, Last process queue ID display, Execute button, Server selection, Security checks | G34: Process step selection, Server group selection, Progress monitoring, Parameter dependencies, Linked reports, Business rules integration, Favorites integration, Real-time execution feedback
A35: QP110 | B35: Active Lock Monitor | C35: N/A | D35: ~85% feature parity achieved (updated 2026-01-14) | E35: 8 identified (3 CRITICAL, 3 MODERATE, 2 LOW) | F35: N/A | G35: N/A
A36: RC010 | B36: Measurement Point Contract Cross Reference | C36: RC010 manages the cross-reference relationships between Measurement Points and Contracts, including related sales contracts for service-type contracts. This is a critical masterfile screen that supports revenue allocation and contract processing workflows. | D36: ~0% feature parity achieved - NO BLAZOR IMPLEMENTATION EXISTS | E36: 45+ identified (35 CRITICAL, 10 MODERATE) | F36: N/A | G36: N/A
A37: RD010 | B37: Reversal DOI Deletion | C37: N/A | D37: ~55% feature parity achieved | E37: 18 identified (8 CRITICAL, 7 MODERATE, 3 LOW) | F37: N/A | G37: N/A
A38: RD015 | B38: Valuation Reversal Source File Query | C38: N/A | D38: ~55% feature parity achieved | E38: 18 identified (9 CRITICAL, 9 MODERATE) | F38: N/A | G38: N/A
A39: SP025 | B39: Well Completion/Property/DOI Xref | C39: N/A | D39: ~35% feature parity achieved | E39: 31 identified (18 CRITICAL, 9 MODERATE, 4 LOW) | F39: N/A | G39: N/A
A40: STG1 | B40: Stage Table Data Maintenance | C40: Manages data imports across 316 staging tables (ASTG, GSTG, KSTG, PSTG, RSTG) with file upload, parsing, validation, and processing | D40: ~15% feature parity achieved (UI prototype only) | E40: 32 identified (18 CRITICAL, 8 MODERATE, 6 LOW) | F40: Basic page layout, Security check, Table selection dropdown (8 hardcoded - non-existent tables), Filter section (Business Segment, Status, Load Date), Results grid prototype, Action buttons (mock), Summary statistics panel, Sample data generation | G40: Complete backend service implementation (0%), 30+ real staging table grid configurations, Dynamic table selection, File upload/parsing engine, Data validation engine, Error tracking, Batch processing integration, Stored procedure execution, TMPL_TYPE_CD/SRC_SYS_CD/PKG_CD management, Status workflow
...

Sheet QFC Features
A1: Major Feature | B1: Minor Feature | C1: Priority for My Q Accounting | D1: General Notes | E1: Status in .Net POC | F1: POC Notes
A2: QFC Security | B2: Screens Use Group Level Security | C2: 1 - Critical | E2: 1
A3: QFC Security | B3: Screen to Add/Modify Users | C3: 1 - Critical | E3: 0.8
A4: QFC Security | B4: Screen to Modify Groups | C4: 1 - Critical | E4: 0.8
A5: Screen Defaults | C5: 2 - Very High
A6: Screen Defaults | B6: Contextual Defaulting
A7: UI Automation Framework
A8: Screen Modified State
A9: Grids
A10: Grids | B10: editable (Enterprise level) | C10: 2 - Very High
A11: Grids | B11: copy paste | C11: 2 - Very High
A12: Grids | B12: bulk update | C12: 2 - Very High
A13: Grids | B13: grid row state / status | C13: 2 - Very High
A14: Grids | B14: deleted row status | C14: 2 - Very High
A15: Pick Lists | B15: Picklists available on screens
A16: Pick Lists | B16: User types and it uses pick list
A17: Pick Lists | B17: Fill in multiple screen values from pick list selection
A18: Notes | C18: 1 - Critical
A19: Documents
A20: Documents | B20: Entity Level Integration
A21: Validation Engine / Framework
A22: Validation Engine / Framework | B22: disable / enable
A23: Code Tables | B23: Drop Downs on Screens
A24: Code Tables | B24: Metadata Driven Code Tables (Customizable)
A25: Code Tables | B25: Code Table Editor
A26: UI Validation Framework
A27: UI Validation Framework | B27: high lighting and tool tip
A28: UI Validation Framework | B28: info / error / warning
A29: UI Validation Framework | B29: bread crumbing
A30: Message Center (centralized logging)
A31: Message Center (centralized logging) | B31: persist across sessions
A32: Application Insights (Heavy messaging)
A33: Report Launching | B33: Report Launcher Screen | C33: 1 - Critical
A34: Report Launching | B34: Launch Reports from Specific Screens | C34: 2 - Very High
A35: Batch Process Launching | B35: Batch Launcher Screen | C35: 1 - Critical
A36: Batch Process Launching | B36: Launch Batch from Specific Screens | C36: 1 - Critical
A37: Quick Search | B37: Screens | C37: 2 - Very High | E37: 1
A38: Quick Search | B38: Reports/Batch | C38: 3 - High
A39: Quick Search | B39: Favorites | C39: 4 - Medium
A40: Screen State (change cart)
...

Sheet To Determine
A1: Grids | B1: Do we need grid definitions that can be configred?
A2: Code Tables | B2: Do we need configurable code tables outside of being able to add values to code tables? Do the screens really need different ones?
A3: Screen Layout | B3: Do we need grid + form for data entry or just for view?
A4: Sessions | B4: Do we need the robust session handling where a user can walk away and come back to their screens all being open with the right data?

Sheet Lookups
A1: Priority | C1: Dev Priority | G1: ID | H1: Title | K1: NAME | L1: CODE | M1: CODE: NAME
A2: 1 - Critical | C2: 1 - Priority 1 | G2: 1786976 | H2: 00 EAM - Screens - Screen Inventory and Prioritization | K2: Accounting Month Roll Date | L2: JE102 | M2: JE102: Accounting Month Roll Date - Smoke Test
A3: 2 - Very High | C3: 2 - Priority 2 | G3: 1790394 | H3: 01 EAM - Foundation - QRA Repo Setup | K3: Check Register Details | L3: CW006 | M3: CW006: Check Register Details - Smoke Test
A4: 3 - High | C4: 3 - Priority 3 | G4: 1790990 | H4: 01.1 EAM - Screens - Mitigate Dual Maintenance During Development | K4: Check Register Query/View | L4: CW005 | M4: CW005: Check Register Query/View - Smoke Test
A5: 4 - Medium | G5: 1798235 | H5: 01.2 EAM - Screens - Verify POC Screens are Functional on .NET 10 | K5: Contract Allocation Flow Grid Desk ID | L5: DI075 | M5: DI075: Contract Allocation Flow Grid Desk ID - Smoke Test
A6: 5 - Low | G6: 1786983 | H6: 01.4 EAM - Foundation - Metadata and Configuration | K6: Contract Desk ID | L6: DI025 | M6: DI025: Contract Desk ID - Smoke Test
A7: 6 - Do Not Need | G7: 1789636 | H7: 02 EAM - Screens - Pilot Screen Robot Training | K7: Contract Maintenance | L7: RC005 | M7: RC005: Contract Maintenance - Smoke Test
G8: 1786972 | H8: 03 EAM - Screens - Direct Revenue Input | K8: Desk ID Flow Grid Summary | L8: DI005 | M8: DI005: Desk ID Flow Grid Summary - Smoke Test
G9: 1792329 | H9: 04 EAM - Screens - Journal Entry - JE Processing Screens | K9: Desk ID Revenue Check Input | L9: DI015 | M9: DI015: Desk ID Revenue Check Input - Smoke Test
G10: 1786978 | H10: 05 EAM - Screens- Journal Entry - Setup Screens | K10: Desk ID Revenue Flow Grid Summary | L10: DI010 | M10: DI010: Desk ID Revenue Flow Grid Summary - Smoke Test
G11: 1786980 | H11: 06 EAM - Screens - Revenue Distribution - Processing | K11: Desk ID Revenue Valuation | L11: DI020 | M11: DI020: Desk ID Revenue Valuation - Smoke Test
G12: 1792384 | H12: 07 EAM - Screens - Revenue Distribution - Setup | K12: Direct Revenue Input | L12: VL031 | M12: VL031: Direct Revenue Input - Smoke Test
G13: 1792996 | H13: 08 EAM - Screens - Advanced Filter Mechanism | K13: Gas Balancing Agreement Desk ID | L13: DI040 | M13: DI040: Gas Balancing Agreement Desk ID - Smoke Test
G14: 1792365 | H14: 09 EAM - Screens - Direct Revenue Input - Upload | K14: Gas Balancing Selection | L14: GB010 | M14: GB010: Gas Balancing Selection - Smoke Test
G15: 1792382 | H15: 10 EAM - Screens - Revenue Distribution - Query Screens | K15: Gas Imbalance Browse | L15: GB020 | M15: GB020: Gas Imbalance Browse - Smoke Test
G16: 1792387 | H16: 11 EAM - Screens - Revenue Distribution - PPN | K16: Gas Reserves Override | L16: GB025 | M16: GB025: Gas Reserves Override - Smoke Test
G17: 1792326 | H17: 12 EAM - Screens - Journal Entry - Query Screens | K17: GL History Detail Query | L17: JE111 | M17: JE111: GL History Detail Query - Smoke Test
G18: 1792325 | H18: 13 EAM - Screens - Journal Entry - Manual Journal Entry Screens | K18: GL MTD Detail Query | L18: JE110 | M18: JE110: GL MTD Detail Query - Smoke Test
G19: 1792327 | H19: 14 EAM - Screens - Journal Entry - Reversal Screens | K19: JE Post Selection/Submittal | L19: JE100 | M19: JE100: JE Post Selection/Submittal - Smoke Test
... G38: 1796623 | H38: EAM - UI/Platform Issues | K38: Well Completion | L38: PD035 | M38: PD035: Well Completion - Smoke Test
K39: Well Property Cross Reference | L39: SP025 | M39: SP025: Well Property Cross Reference - Smoke Test
